Workbook

Sheet Assumptions
A1: WAYPOINT FINANCIAL MODEL V3 — FORMULA-DRIVEN
A2: Feb 2026 | Blue cells = editable inputs. Monthly P&L auto-calculates from these. Col D = formula reference keys.
A4: PRICING
A5: Navigator tier (monthly) | B5: 9.99 | D5: NAV_PRICE
A6: Navigator Pro tier (monthly) | B6: 19.99 | D6: PRO_PRICE
A7: Pro tier % of paid subscribers | B7: 0.25 | D7: PRO_PCT
A8: IEPClarity avg purchase price | B8: 39 | C8: $29-69 range | D8: IEP_AVG
A9: RC reimbursement per user/month | B9: =B5*(1-B7)+B6*B7 -> 12.49 | C9: Blended ARPU (same as consumer). RC pays, family pays $0. | D9: RC_RATE
A10: B2B provider listing (monthly) | B10: 100 | D10: B2B_RATE
A12: SUBSCRIBER GROWTH
A13: Month 1 new paid subscribers | B13: 3 | C13: Solo founder, organic only | D13: BASE_NEW
A14: Monthly growth rate (Mo 1-6) | B14: 0.25 | C14: FB groups, Reddit, personal network | D14: GROW_1_6
A15: Monthly growth rate (Mo 7-12) | B15: 0.15 | C15: IEPClarity funnel + advocates | D15: GROW_7_12
A16: Monthly growth rate (Mo 13-18) | B16: 0.1 | D16: GROW_13_18
A17: Monthly growth rate (Mo 19-24) | B17: 0.08 | D17: GROW_19_24
A18: Monthly churn rate | B18: 0.07 | C18: 7% = realistic pre-PMF | D18: CHURN
A19: Organic subscriber ceiling (logistic cap) | B19: 400 | C19: Channels saturate ~400 subs w/o paid acq | D19: SUB_CAP
A21: RC REIMBURSEMENT
A22: RC pilot start month | B22: 9 | C22: Month 9: RC bureaucracy | D22: RC_START
A23: Initial RC users (pilot) | B23: 5 | C23: Small pilot | D23: RC_INIT
A24: RC monthly growth rate (early) | B24: 0.2 | C24: 20% monthly = institutional adoption curve | D24: RC_GROW_PCT
A25: RC monthly growth rate (Mo 13+) | B25: 0.15 | C25: 15% = maturation after initial rollout | D25: RC_GROW_PCT_13
A26: RC monthly churn rate | B26: 0.03 | C26: 3% = institutional stickiness | D26: RC_CHURN
A27: IEPCLARITY FEEDER
A28: IEPClarity launch month | B28: 3 | D28: IEP_START
A29: IEPClarity monthly new customers (base) | B29: 3 | C29: Steady monthly volume | D29: IEP_BASE
A30: IEPClarity monthly growth rate | B30: 0.2 | C30: Grows 20%/mo from base | D30: IEP_GROW
A31: IEPClarity → Waypoint conversion | B31: 0.05 | C31: 5% = unproven | D31: IEP_CONV
A33: B2B DIRECTORY
A34: B2B launch month | B34: 10 | D34: B2B_START
A35: Initial B2B listings | B35: 2 | D35: B2B_INIT
A36: Monthly B2B growth | B36: 1 | D36: B2B_GROW
A38: VARIABLE COSTS
A39: Claude API cost per user/month | B39: 1.25 | C39: $1.25 = buffer | D39: API_COST
A40: Infrastructure base (monthly) | B40: 75 | D40: INFRA_BASE
A41: Infrastructure per-user | B41: 0.2 | D41: INFRA_PER
A42: SMS cost per user/month | B42: 0.12 | D42: SMS_PER
A44: FIXED COSTS
A45: Domain + SaaS tools (monthly) | B45: 60 | D45: DOMAIN
A46: Marketing (Mo 1-6) | B46: 150 | D46: MKTG_1_6
...

Sheet Monthly P&L
B1: Mar 2026 | C1: Apr 2026 | D1: May 2026 | E1: Jun 2026 | F1: Jul 2026 | G1: Aug 2026 | H1: Sep 2026 | I1: Oct 2026 | J1: Nov 2026 | K1: Dec 2026 | L1: Jan 2027 | M1: Feb 2027 | N1: Mar 2027 | O1: Apr 2027 | P1: May 2027 | Q1: Jun 2027 | R1: Jul 2027 | S1: Aug 2027 | T1: Sep 2027 | U1: Oct 2027 | V1: Nov 2027 | W1: Dec 2027 | X1: Jan 2028 | Y1: Feb 2028 | Z1: 24-Mo Total
A2: SUBSCRIBER METRICS
A3: New Paid Subscribers | B3: =Assumptions!$B$13 -> 3 | C3: =MIN(MAX(ROUND(Assumptions!$B$13*(1+IF(2<=6,Assumptions!$B$14,IF(2<=12,Assumptions!$B$15,IF(2<=18,Assumptions!$B$16,Assumptions!$B$17))))^1,0),Assumptions!$B$13),50) -> 4 | D3: =MIN(MAX(ROUND(Assumptions!$B$13*(1+IF(3<=6,Assumptions!$B$14,IF(3<=12,Assumptions!$B$15,IF(3<=18,Assumptions!$B$16,Assumptions!$B$17))))^2,0),Assumptions!$B$13),50) -> 5 | E3: =MIN(MAX(ROUND(Assumptions!$B$13*(1+IF(4<=6,Assumptions!$B$14,IF(4<=12,Assumptions!$B$15,IF(4<=18,Assumptions!$B$16,Assumptions!$B$17))))^3,0),Assumptions!$B$13),50) -> 6 | F3: =MIN(MAX(ROUND(Assumptions!$B$13*(1+IF(5<=6,Assumptions!$B$14,IF(5<=12,Assumptions!$B$15,IF(5<=18,Assumptions!$B$16,Assumptions!$B$17))))^4,0),Assumptions!$B$13),50) -> 7 | G3: =MIN(MAX(ROUND(Assumptions!$B$13*(1+IF(6<=6,Assumptions!$B$14,IF(6<=12,Assumptions!$B$15,IF(6<=18,Assumptions!$B$16,Assumptions!$B$17))))^5,0),Assumptions!$B$13),50) -> 9 | H3: =MIN(MAX(ROUND(Assumptions!$B$13*(1+IF(7<=6,Assumptions!$B$14,IF(7<=12,Assumptions!$B$15,IF(7<=18,Assumptions!$B$16,Assumptions!$B$17))))^6,0),Assumptions!$B$13),50) -> 7 | I3: =MIN(MAX(ROUND(Assumptions!$B$13*(1+IF(8<=6,Assumptions!$B$14,IF(8<=12,Assumptions!$B$15,IF(8<=18,Assumptions!$B$16,Assumptions!$B$17))))^7,0),Assumptions!$B$13),50) -> 8 | J3: =MIN(MAX(ROUND(Assumptions!$B$13*(1+IF(9<=6,Assumptions!$B$14,IF(9<=12,Assumptions!$B$15,IF(9<=18,Assumptions!$B$16,Assumptions!$B$17))))^8,0),Assumptions!$B$13),50) -> 9 | K3: =MIN(MAX(ROUND(Assumptions!$B$13*(1+IF(10<=6,Assumptions!$B$14,IF(10<=12,Assumptions!$B$15,IF(10<=18,Assumptions!$B$16,Assumptions!$B$17))))^9,0),Assumptions!$B$13),50) -> 11 | L3: =MIN(MAX(ROUND(Assumptions!$B$13*(1+IF(11<=6,Assumptions!$B$14,IF(11<=12,Assumptions!$B$15,IF(11<=18,Assumptions!$B$16,Assumptions!$B$17))))^10,0),Assumptions!$B$13),50) -> 12 | M3: =MIN(MAX(ROUND(Assumptions!$B$13*(1+IF(12<=6,Assumptions!$B$14,IF(12<=12,Assumptions!$B$15,IF(12<=18,Assumptions!$B$16,Assumptions!$B$17))))^11,0),Assumptions!$B$13),50) -> 14 | N3: =MIN(MAX(ROUND(Assumptions!$B$13*(1+IF(13<=6,Assumptions!$B$14,IF(13<=12,Assumptions!$B$15,IF(13<=18,Assumptions!$B$16,Assumptions!$B$17))))^12,0),Assumptions!$B$13),50) -> 9 | O3: =MIN(MAX(ROUND(Assumptions!$B$13*(1+IF(14<=6,Assumptions!$B$14,IF(14<=12,Assumptions!$B$15,IF(14<=18,Assumptions!$B$16,Assumptions!$B$17))))^13,0),Assumptions!$B$13),50) -> 10 | P3: =MIN(MAX(ROUND(Assumptions!$B$13*(1+IF(15<=6,Assumptions!$B$14,IF(15<=12,Assumptions!$B$15,IF(15<=18,Assumptions!$B$16,Assumptions!$B$17))))^14,0),Assumptions!$B$13),50) -> 11 | Q3: =MIN(MAX(ROUND(Assumptions!$B$13*(1+IF(16<=6,Assumptions!$B$14,IF(16<=12,Assumptions!$B$15,IF(16<=18,Assumptions!$B$16,Assumptions!$B$17))))^15,0),Assumptions!$B$13),50) -> 13 | R3: =MIN(MAX(ROUND(Assumptions!$B$13*(1+IF(17<=6,Assumptions!$B$14,IF(17<=12,Assumptions!$B$15,IF(17<=18,Assumptions!$B$16,Assumptions!$B$17))))^16,0),Assumptions!$B$13),50) -> 14 | S3: =MIN(MAX(ROUND(Assumptions!$B$13*(1+IF(18<=6,Assumptions!$B$14,IF(18<=12,Assumptions!$B$15,IF(18<=18,Assumptions!$B$16,Assumptions!$B$17))))^17,0),Assumptions!$B$13),50) -> 15 | T3: =MIN(MAX(ROUND(Assumptions!$B$13*(1+IF(19<=6,Assumptions!$B$14,IF(19<=12,Assumptions!$B$15,IF(19<=18,Assumptions!$B$16,Assumptions!$B$17))))^18,0),Assumptions!$B$13),50) -> 12 | U3: =MIN(MAX(ROUND(Assumptions!$B$13*(1+IF(20<=6,Assumptions!$B$14,IF(20<=12,Assumptions!$B$15,IF(20<=18,Assumptions!$B$16,Assumptions!$B$17))))^19,0),Assumptions!$B$13),50) -> 13 | V3: =MIN(MAX(ROUND(Assumptions!$B$13*(1+IF(21<=6,Assumptions!$B$14,IF(21<=12,Assumptions!$B$15,IF(21<=18,Assumptions!$B$16,Assumptions!$B$17))))^20,0),Assumptions!$B$13),50) -> 14 | W3: =MIN(MAX(ROUND(Assumptions!$B$13*(1+IF(22<=6,Assumptions!$B$14,IF(22<=12,Assumptions!$B$15,IF(22<=18,Assumptions!$B$16,Assumptions!$B$17))))^21,0),Assumptions!$B$13),50) -> 15 | X3: =MIN(MAX(ROUND(Assumptions!$B$13*(1+IF(23<=6,Assumptions!$B$14,IF(23<=12,Assumptions!$B$15,IF(23<=18,Assumptions!$B$16,Assumptions!$B$17))))^22,0),Assumptions!$B$13),50) -> 16 | Y3: =MIN(MAX(ROUND(Assumptions!$B$13*(1+IF(24<=6,Assumptions!$B$14,IF(24<=12,Assumptions!$B$15,IF(24<=18,Assumptions!$B$16,Assumptions!$B$17))))^23,0),Assumptions!$B$13),50) -> 18 | Z3: =SUM(B3:Y3) -> 255
A4: Churned Subscribers | B4: 0 | C4: =ROUND(B5*Assumptions!$B$18,0) -> 0 | D4: =ROUND(C5*Assumptions!$B$18,0) -> 0 | E4: =ROUND(D5*Assumptions!$B$18,0) -> 1 | F4: =ROUND(E5*Assumptions!$B$18,0) -> 1 | G4: =ROUND(F5*Assumptions!$B$18,0) -> 2 | H4: =ROUND(G5*Assumptions!$B$18,0) -> 2 | I4: =ROUND(H5*Assumptions!$B$18,0) -> 2 | J4: =ROUND(I5*Assumptions!$B$18,0) -> 3 | ... Y4: =ROUND(X5*Assumptions!$B$18,0) -> 10 | Z4: =SUM(B4:Y4) -> 110
A5: Total Paid Subscribers | B5: =Assumptions!$B$13 -> 3 | C5: =IF((B5+C3-C4)<Assumptions!$B$19*0.5,(B5+C3-C4),MIN((B5+C3-C4),Assumptions!$B$19)) -> 7 | D5: =IF((C5+D3-D4)<Assumptions!$B$19*0.5,(C5+D3-D4),MIN((C5+D3-D4),Assumptions!$B$19)) -> 12 | E5: =IF((D5+E3-E4)<Assumptions!$B$19*0.5,(D5+E3-E4),MIN((D5+E3-E4),Assumptions!$B$19)) -> 17 | F5: =IF((E5+F3-F4)<Assumptions!$B$19*0.5,(E5+F3-F4),MIN((E5+F3-F4),Assumptions!$B$19)) -> 23 | G5: =IF((F5+G3-G4)<Assumptions!$B$19*0.5,(F5+G3-G4),MIN((F5+G3-G4),Assumptions!$B$19)) -> 30 | H5: =IF((G5+H3-H4)<Assumptions!$B$19*0.5,(G5+H3-H4),MIN((G5+H3-H4),Assumptions!$B$19)) -> 35 | I5: =IF((H5+I3-I4)<Assumptions!$B$19*0.5,(H5+I3-I4),MIN((H5+I3-I4),Assumptions!$B$19)) -> 41 | J5: =IF((I5+J3-J4)<Assumptions!$B$19*0.5,(I5+J3-J4),MIN((I5+J3-J4),Assumptions!$B$19)) -> 47 | ... Y5: =IF((X5+Y3-Y4)<Assumptions!$B$19*0.5,(X5+Y3-Y4),MIN((X5+Y3-Y4),Assumptions!$B$19)) -> 145 | Z5: =Y5 -> 145
A6: RC Reimbursed Users | B6: =IF(1<Assumptions!$B$22,0,Assumptions!$B$23) -> 0 | C6: =IF(2<Assumptions!$B$22,0,IF(2=Assumptions!$B$22,Assumptions!$B$23,(B6+ROUND(B6*IF(2<=12,Assumptions!$B$24,Assumptions!$B$25),0)-ROUND(B6*Assumptions!$B$26,0)))) -> 0 | D6: =IF(3<Assumptions!$B$22,0,IF(3=Assumptions!$B$22,Assumptions!$B$23,(C6+ROUND(C6*IF(3<=12,Assumptions!$B$24,Assumptions!$B$25),0)-ROUND(C6*Assumptions!$B$26,0)))) -> 0 | E6: =IF(4<Assumptions!$B$22,0,IF(4=Assumptions!$B$22,Assumptions!$B$23,(D6+ROUND(D6*IF(4<=12,Assumptions!$B$24,Assumptions!$B$25),0)-ROUND(D6*Assumptions!$B$26,0)))) -> 0 | F6: =IF(5<Assumptions!$B$22,0,IF(5=Assumptions!$B$22,Assumptions!$B$23,(E6+ROUND(E6*IF(5<=12,Assumptions!$B$24,Assumptions!$B$25),0)-ROUND(E6*Assumptions!$B$26,0)))) -> 0 | G6: =IF(6<Assumptions!$B$22,0,IF(6=Assumptions!$B$22,Assumptions!$B$23,(F6+ROUND(F6*IF(6<=12,Assumptions!$B$24,Assumptions!$B$25),0)-ROUND(F6*Assumptions!$B$26,0)))) -> 0 | H6: =IF(7<Assumptions!$B$22,0,IF(7=Assumptions!$B$22,Assumptions!$B$23,(G6+ROUND(G6*IF(7<=12,Assumptions!$B$24,Assumptions!$B$25),0)-ROUND(G6*Assumptions!$B$26,0)))) -> 0 | I6: =IF(8<Assumptions!$B$22,0,IF(8=Assumptions!$B$22,Assumptions!$B$23,(H6+ROUND(H6*IF(8<=12,Assumptions!$B$24,Assumptions!$B$25),0)-ROUND(H6*Assumptions!$B$26,0)))) -> 0 | J6: =IF(9<Assumptions!$B$22,0,IF(9=Assumptions!$B$22,Assumptions!$B$23,(I6+ROUND(I6*IF(9<=12,Assumptions!$B$24,Assumptions!$B$25),0)-ROUND(I6*Assumptions!$B$26,0)))) -> 5 | K6: =IF(10<Assumptions!$B$22,0,IF(10=Assumptions!$B$22,Assumptions!$B$23,(J6+ROUND(J6*IF(10<=12,Assumptions!$B$24,Assumptions!$B$25),0)-ROUND(J6*Assumptions!$B$26,0)))) -> 6 | L6: =IF(11<Assumptions!$B$22,0,IF(11=Assumptions!$B$22,Assumptions!$B$23,(K6+ROUND(K6*IF(11<=12,Assumptions!$B$24,Assumptions!$B$25),0)-ROUND(K6*Assumptions!$B$26,0)))) -> 7 | M6: =IF(12<Assumptions!$B$22,0,IF(12=Assumptions!$B$22,Assumptions!$B$23,(L6+ROUND(L6*IF(12<=12,Assumptions!$B$24,Assumptions!$B$25),0)-ROUND(L6*Assumptions!$B$26,0)))) -> 8 | N6: =IF(13<Assumptions!$B$22,0,IF(13=Assumptions!$B$22,Assumptions!$B$23,(M6+ROUND(M6*IF(13<=12,Assumptions!$B$24,Assumptions!$B$25),0)-ROUND(M6*Assumptions!$B$26,0)))) -> 9 | O6: =IF(14<Assumptions!$B$22,0,IF(14=Assumptions!$B$22,Assumptions!$B$23,(N6+ROUND(N6*IF(14<=12,Assumptions!$B$24,Assumptions!$B$25),0)-ROUND(N6*Assumptions!$B$26,0)))) -> 10 | P6: =IF(15<Assumptions!$B$22,0,IF(15=Assumptions!$B$22,Assumptions!$B$23,(O6+ROUND(O6*IF(15<=12,Assumptions!$B$24,Assumptions!$B$25),0)-ROUND(O6*Assumptions!$B$26,0)))) -> 12 | Q6: =IF(16<Assumptions!$B$22,0,IF(16=Assumptions!$B$22,Assumptions!$B$23,(P6+ROUND(P6*IF(16<=12,Assumptions!$B$24,Assumptions!$B$25),0)-ROUND(P6*Assumptions!$B$26,0)))) -> 14 | R6: =IF(17<Assumptions!$B$22,0,IF(17=Assumptions!$B$22,Assumptions!$B$23,(Q6+ROUND(Q6*IF(17<=12,Assumptions!$B$24,Assumptions!$B$25),0)-ROUND(Q6*Assumptions!$B$26,0)))) -> 16 | S6: =IF(18<Assumptions!$B$22,0,IF(18=Assumptions!$B$22,Assumptions!$B$23,(R6+ROUND(R6*IF(18<=12,Assumptions!$B$24,Assumptions!$B$25),0)-ROUND(R6*Assumptions!$B$26,0)))) -> 18 | T6: =IF(19<Assumptions!$B$22,0,IF(19=Assumptions!$B$22,Assumptions!$B$23,(S6+ROUND(S6*IF(19<=12,Assumptions!$B$24,Assumptions!$B$25),0)-ROUND(S6*Assumptions!$B$26,0)))) -> 20 | U6: =IF(20<Assumptions!$B$22,0,IF(20=Assumptions!$B$22,Assumptions!$B$23,(T6+ROUND(T6*IF(20<=12,Assumptions!$B$24,Assumptions!$B$25),0)-ROUND(T6*Assumptions!$B$26,0)))) -> 22 | V6: =IF(21<Assumptions!$B$22,0,IF(21=Assumptions!$B$22,Assumptions!$B$23,(U6+ROUND(U6*IF(21<=12,Assumptions!$B$24,Assumptions!$B$25),0)-ROUND(U6*Assumptions!$B$26,0)))) -> 24 | W6: =IF(22<Assumptions!$B$22,0,IF(22=Assumptions!$B$22,Assumptions!$B$23,(V6+ROUND(V6*IF(22<=12,Assumptions!$B$24,Assumptions!$B$25),0)-ROUND(V6*Assumptions!$B$26,0)))) -> 27 | X6: =IF(23<Assumptions!$B$22,0,IF(23=Assumptions!$B$22,Assumptions!$B$23,(W6+ROUND(W6*IF(23<=12,Assumptions!$B$24,Assumptions!$B$25),0)-ROUND(W6*Assumptions!$B$26,0)))) -> 30 | Y6: =IF(24<Assumptions!$B$22,0,IF(24=Assumptions!$B$22,Assumptions!$B$23,(X6+ROUND(X6*IF(24<=12,Assumptions!$B$24,Assumptions!$B$25),0)-ROUND(X6*Assumptions!$B$26,0)))) -> 34 | Z6: =Y6 -> 34
A7: IEPClarity New Purchases | B7: =IF(1<Assumptions!$B$28,0,MIN(MAX(1,ROUND(Assumptions!$B$29*(1+Assumptions!$B$30)^(1-Assumptions!$B$28),0)),25)) -> 0 | C7: =IF(2<Assumptions!$B$28,0,MIN(MAX(1,ROUND(Assumptions!$B$29*(1+Assumptions!$B$30)^(2-Assumptions!$B$28),0)),25)) -> 0 | D7: =IF(3<Assumptions!$B$28,0,MIN(MAX(1,ROUND(Assumptions!$B$29*(1+Assumptions!$B$30)^(3-Assumptions!$B$28),0)),25)) -> 3 | E7: =IF(4<Assumptions!$B$28,0,MIN(MAX(1,ROUND(Assumptions!$B$29*(1+Assumptions!$B$30)^(4-Assumptions!$B$28),0)),25)) -> 4 | F7: =IF(5<Assumptions!$B$28,0,MIN(MAX(1,ROUND(Assumptions!$B$29*(1+Assumptions!$B$30)^(5-Assumptions!$B$28),0)),25)) -> 4 | G7: =IF(6<Assumptions!$B$28,0,MIN(MAX(1,ROUND(Assumptions!$B$29*(1+Assumptions!$B$30)^(6-Assumptions!$B$28),0)),25)) -> 5 | H7: =IF(7<Assumptions!$B$28,0,MIN(MAX(1,ROUND(Assumptions!$B$29*(1+Assumptions!$B$30)^(7-Assumptions!$B$28),0)),25)) -> 6 | I7: =IF(8<Assumptions!$B$28,0,MIN(MAX(1,ROUND(Assumptions!$B$29*(1+Assumptions!$B$30)^(8-Assumptions!$B$28),0)),25)) -> 7 | J7: =IF(9<Assumptions!$B$28,0,MIN(MAX(1,ROUND(Assumptions!$B$29*(1+Assumptions!$B$30)^(9-Assumptions!$B$28),0)),25)) -> 9 | K7: =IF(10<Assumptions!$B$28,0,MIN(MAX(1,ROUND(Assumptions!$B$29*(1+Assumptions!$B$30)^(10-Assumptions!$B$28),0)),25)) -> 11 | L7: =IF(11<Assumptions!$B$28,0,MIN(MAX(1,ROUND(Assumptions!$B$29*(1+Assumptions!$B$30)^(11-Assumptions!$B$28),0)),25)) -> 13 | M7: =IF(12<Assumptions!$B$28,0,MIN(MAX(1,ROUND(Assumptions!$B$29*(1+Assumptions!$B$30)^(12-Assumptions!$B$28),0)),25)) -> 15 | N7: =IF(13<Assumptions!$B$28,0,MIN(MAX(1,ROUND(Assumptions!$B$29*(1+Assumptions!$B$30)^(13-Assumptions!$B$28),0)),25)) -> 19 | O7: =IF(14<Assumptions!$B$28,0,MIN(MAX(1,ROUND(Assumptions!$B$29*(1+Assumptions!$B$30)^(14-Assumptions!$B$28),0)),25)) -> 22 | P7: =IF(15<Assumptions!$B$28,0,MIN(MAX(1,ROUND(Assumptions!$B$29*(1+Assumptions!$B$30)^(15-Assumptions!$B$28),0)),25)) -> 25 | Q7: =IF(16<Assumptions!$B$28,0,MIN(MAX(1,ROUND(Assumptions!$B$29*(1+Assumptions!$B$30)^(16-Assumptions!$B$28),0)),25)) -> 25 | R7: =IF(17<Assumptions!$B$28,0,MIN(MAX(1,ROUND(Assumptions!$B$29*(1+Assumptions!$B$30)^(17-Assumptions!$B$28),0)),25)) -> 25 | S7: =IF(18<Assumptions!$B$28,0,MIN(MAX(1,ROUND(Assumptions!$B$29*(1+Assumptions!$B$30)^(18-Assumptions!$B$28),0)),25)) -> 25 | T7: =IF(19<Assumptions!$B$28,0,MIN(MAX(1,ROUND(Assumptions!$B$29*(1+Assumptions!$B$30)^(19-Assumptions!$B$28),0)),25)) -> 25 | U7: =IF(20<Assumptions!$B$28,0,MIN(MAX(1,ROUND(Assumptions!$B$29*(1+Assumptions!$B$30)^(20-Assumptions!$B$28),0)),25)) -> 25 | V7: =IF(21<Assumptions!$B$28,0,MIN(MAX(1,ROUND(Assumptions!$B$29*(1+Assumptions!$B$30)^(21-Assumptions!$B$28),0)),25)) -> 25 | W7: =IF(22<Assumptions!$B$28,0,MIN(MAX(1,ROUND(Assumptions!$B$29*(1+Assumptions!$B$30)^(22-Assumptions!$B$28),0)),25)) -> 25 | X7: =IF(23<Assumptions!$B$28,0,MIN(MAX(1,ROUND(Assumptions!$B$29*(1+Assumptions!$B$30)^(23-Assumptions!$B$28),0)),25)) -> 25 | Y7: =IF(24<Assumptions!$B$28,0,MIN(MAX(1,ROUND(Assumptions!$B$29*(1+Assumptions!$B$30)^(24-Assumptions!$B$28),0)),25)) -> 25 | Z7: =SUM(B7:Y7) -> 368
A8: B2B Provider Listings | B8: =IF(1<Assumptions!$B$34,0,MIN(Assumptions!$B$35+(1-Assumptions!$B$34)*Assumptions!$B$36,30)) -> 0 | C8: =IF(2<Assumptions!$B$34,0,MIN(Assumptions!$B$35+(2-Assumptions!$B$34)*Assumptions!$B$36,30)) -> 0 | D8: =IF(3<Assumptions!$B$34,0,MIN(Assumptions!$B$35+(3-Assumptions!$B$34)*Assumptions!$B$36,30)) -> 0 | E8: =IF(4<Assumptions!$B$34,0,MIN(Assumptions!$B$35+(4-Assumptions!$B$34)*Assumptions!$B$36,30)) -> 0 | F8: =IF(5<Assumptions!$B$34,0,MIN(Assumptions!$B$35+(5-Assumptions!$B$34)*Assumptions!$B$36,30)) -> 0 | G8: =IF(6<Assumptions!$B$34,0,MIN(Assumptions!$B$35+(6-Assumptions!$B$34)*Assumptions!$B$36,30)) -> 0 | H8: =IF(7<Assumptions!$B$34,0,MIN(Assumptions!$B$35+(7-Assumptions!$B$34)*Assumptions!$B$36,30)) -> 0 | I8: =IF(8<Assumptions!$B$34,0,MIN(Assumptions!$B$35+(8-Assumptions!$B$34)*Assumptions!$B$36,30)) -> 0 | J8: =IF(9<Assumptions!$B$34,0,MIN(Assumptions!$B$35+(9-Assumptions!$B$34)*Assumptions!$B$36,30)) -> 0 | K8: =IF(10<Assumptions!$B$34,0,MIN(Assumptions!$B$35+(10-Assumptions!$B$34)*Assumptions!$B$36,30)) -> 2 | L8: =IF(11<Assumptions!$B$34,0,MIN(Assumptions!$B$35+(11-Assumptions!$B$34)*Assumptions!$B$36,30)) -> 3 | M8: =IF(12<Assumptions!$B$34,0,MIN(Assumptions!$B$35+(12-Assumptions!$B$34)*Assumptions!$B$36,30)) -> 4 | N8: =IF(13<Assumptions!$B$34,0,MIN(Assumptions!$B$35+(13-Assumptions!$B$34)*Assumptions!$B$36,30)) -> 5 | O8: =IF(14<Assumptions!$B$34,0,MIN(Assumptions!$B$35+(14-Assumptions!$B$34)*Assumptions!$B$36,30)) -> 6 | P8: =IF(15<Assumptions!$B$34,0,MIN(Assumptions!$B$35+(15-Assumptions!$B$34)*Assumptions!$B$36,30)) -> 7 | Q8: =IF(16<Assumptions!$B$34,0,MIN(Assumptions!$B$35+(16-Assumptions!$B$34)*Assumptions!$B$36,30)) -> 8 | R8: =IF(17<Assumptions!$B$34,0,MIN(Assumptions!$B$35+(17-Assumptions!$B$34)*Assumptions!$B$36,30)) -> 9 | S8: =IF(18<Assumptions!$B$34,0,MIN(Assumptions!$B$35+(18-Assumptions!$B$34)*Assumptions!$B$36,30)) -> 10 | T8: =IF(19<Assumptions!$B$34,0,MIN(Assumptions!$B$35+(19-Assumptions!$B$34)*Assumptions!$B$36,30)) -> 11 | U8: =IF(20<Assumptions!$B$34,0,MIN(Assumptions!$B$35+(20-Assumptions!$B$34)*Assumptions!$B$36,30)) -> 12 | V8: =IF(21<Assumptions!$B$34,0,MIN(Assumptions!$B$35+(21-Assumptions!$B$34)*Assumptions!$B$36,30)) -> 13 | W8: =IF(22<Assumptions!$B$34,0,MIN(Assumptions!$B$35+(22-Assumptions!$B$34)*Assumptions!$B$36,30)) -> 14 | X8: =IF(23<Assumptions!$B$34,0,MIN(Assumptions!$B$35+(23-Assumptions!$B$34)*Assumptions!$B$36,30)) -> 15 | Y8: =IF(24<Assumptions!$B$34,0,MIN(Assumptions!$B$35+(24-Assumptions!$B$34)*Assumptions!$B$36,30)) -> 16 | Z8: =Y8 -> 16
A10: REVENUE
A11: Consumer Subscription Revenue | B11: =ROUND(B5*(Assumptions!$B$5*(1-Assumptions!$B$7)+Assumptions!$B$6*Assumptions!$B$7),0) -> 37 | C11: =ROUND(C5*(Assumptions!$B$5*(1-Assumptions!$B$7)+Assumptions!$B$6*Assumptions!$B$7),0) -> 87 | D11: =ROUND(D5*(Assumptions!$B$5*(1-Assumptions!$B$7)+Assumptions!$B$6*Assumptions!$B$7),0) -> 150 | E11: =ROUND(E5*(Assumptions!$B$5*(1-Assumptions!$B$7)+Assumptions!$B$6*Assumptions!$B$7),0) -> 212 | F11: =ROUND(F5*(Assumptions!$B$5*(1-Assumptions!$B$7)+Assumptions!$B$6*Assumptions!$B$7),0) -> 287 | G11: =ROUND(G5*(Assumptions!$B$5*(1-Assumptions!$B$7)+Assumptions!$B$6*Assumptions!$B$7),0) -> 375 | H11: =ROUND(H5*(Assumptions!$B$5*(1-Assumptions!$B$7)+Assumptions!$B$6*Assumptions!$B$7),0) -> 437 | I11: =ROUND(I5*(Assumptions!$B$5*(1-Assumptions!$B$7)+Assumptions!$B$6*Assumptions!$B$7),0) -> 512 | ... Y11: =ROUND(Y5*(Assumptions!$B$5*(1-Assumptions!$B$7)+Assumptions!$B$6*Assumptions!$B$7),0) -> 1811 | Z11: =SUM(B11:Y11) -> 21519
A12: RC Reimbursement Revenue | B12: =ROUND(B6*Assumptions!$B$9,0) -> 0 | C12: =ROUND(C6*Assumptions!$B$9,0) -> 0 | D12: =ROUND(D6*Assumptions!$B$9,0) -> 0 | E12: =ROUND(E6*Assumptions!$B$9,0) -> 0 | F12: =ROUND(F6*Assumptions!$B$9,0) -> 0 | G12: =ROUND(G6*Assumptions!$B$9,0) -> 0 | H12: =ROUND(H6*Assumptions!$B$9,0) -> 0 | I12: =ROUND(I6*Assumptions!$B$9,0) -> 0 | ... Y12: =ROUND(Y6*Assumptions!$B$9,0) -> 425 | Z12: =SUM(B12:Y12) -> 3273
A13: IEPClarity Revenue | B13: =B7*Assumptions!$B$8 -> 0 | C13: =C7*Assumptions!$B$8 -> 0 | D13: =D7*Assumptions!$B$8 -> 117 | E13: =E7*Assumptions!$B$8 -> 156 | F13: =F7*Assumptions!$B$8 -> 156 | G13: =G7*Assumptions!$B$8 -> 195 | H13: =H7*Assumptions!$B$8 -> 234 | I13: =I7*Assumptions!$B$8 -> 273 | ... Y13: =Y7*Assumptions!$B$8 -> 975 | Z13: =SUM(B13:Y13) -> 14352
A14: B2B Directory Revenue | B14: =B8*Assumptions!$B$10 -> 0 | C14: =C8*Assumptions!$B$10 -> 0 | D14: =D8*Assumptions!$B$10 -> 0 | E14: =E8*Assumptions!$B$10 -> 0 | F14: =F8*Assumptions!$B$10 -> 0 | G14: =G8*Assumptions!$B$10 -> 0 | H14: =H8*Assumptions!$B$10 -> 0 | I14: =I8*Assumptions!$B$10 -> 0 | ... Y14: =Y8*Assumptions!$B$10 -> 1600 | Z14: =SUM(B14:Y14) -> 13500
A15: TOTAL REVENUE | B15: =B11+B12+B13+B14 -> 37 | C15: =C11+C12+C13+C14 -> 87 | D15: =D11+D12+D13+D14 -> 267 | E15: =E11+E12+E13+E14 -> 368 | F15: =F11+F12+F13+F14 -> 443 | G15: =G11+G12+G13+G14 -> 570 | H15: =H11+H12+H13+H14 -> 671 | I15: =I11+I12+I13+I14 -> 785 | ... Y15: =Y11+Y12+Y13+Y14 -> 4811 | Z15: =SUM(B15:Y15) -> 52644
A17: COSTS
A18: AI API Costs (Claude) | B18: =ROUND((B5+B6)*Assumptions!$B$39,0) -> 4 | C18: =ROUND((C5+C6)*Assumptions!$B$39,0) -> 9 | D18: =ROUND((D5+D6)*Assumptions!$B$39,0) -> 15 | E18: =ROUND((E5+E6)*Assumptions!$B$39,0) -> 21 | F18: =ROUND((F5+F6)*Assumptions!$B$39,0) -> 29 | G18: =ROUND((G5+G6)*Assumptions!$B$39,0) -> 38 | H18: =ROUND((H5+H6)*Assumptions!$B$39,0) -> 44 | I18: =ROUND((I5+I6)*Assumptions!$B$39,0) -> 51 | ... Y18: =ROUND((Y5+Y6)*Assumptions!$B$39,0) -> 224 | Z18: =SUM(B18:Y18) -> 2483
A19: Infrastructure (Vercel/Supabase) | B19: =ROUND(Assumptions!$B$40+(B5+B6)*Assumptions!$B$41,0) -> 76 | C19: =ROUND(Assumptions!$B$40+(C5+C6)*Assumptions!$B$41,0) -> 76 | D19: =ROUND(Assumptions!$B$40+(D5+D6)*Assumptions!$B$41,0) -> 77 | E19: =ROUND(Assumptions!$B$40+(E5+E6)*Assumptions!$B$41,0) -> 78 | F19: =ROUND(Assumptions!$B$40+(F5+F6)*Assumptions!$B$41,0) -> 80 | G19: =ROUND(Assumptions!$B$40+(G5+G6)*Assumptions!$B$41,0) -> 81 | H19: =ROUND(Assumptions!$B$40+(H5+H6)*Assumptions!$B$41,0) -> 82 | I19: =ROUND(Assumptions!$B$40+(I5+I6)*Assumptions!$B$41,0) -> 83 | ... Y19: =ROUND(Assumptions!$B$40+(Y5+Y6)*Assumptions!$B$41,0) -> 111 | Z19: =SUM(B19:Y19) -> 2195
A20: SMS Costs (Twilio) | B20: =ROUND((B5+B6)*Assumptions!$B$42,0) -> 0 | C20: =ROUND((C5+C6)*Assumptions!$B$42,0) -> 1 | D20: =ROUND((D5+D6)*Assumptions!$B$42,0) -> 1 | E20: =ROUND((E5+E6)*Assumptions!$B$42,0) -> 2 | F20: =ROUND((F5+F6)*Assumptions!$B$42,0) -> 3 | G20: =ROUND((G5+G6)*Assumptions!$B$42,0) -> 4 | H20: =ROUND((H5+H6)*Assumptions!$B$42,0) -> 4 | I20: =ROUND((I5+I6)*Assumptions!$B$42,0) -> 5 | ... Y20: =ROUND((Y5+Y6)*Assumptions!$B$42,0) -> 21 | Z20: =SUM(B20:Y20) -> 237
A21: Domain + SaaS Tools | B21: =Assumptions!$B$45 -> 60 | C21: =Assumptions!$B$45 -> 60 | D21: =Assumptions!$B$45 -> 60 | E21: =Assumptions!$B$45 -> 60 | F21: =Assumptions!$B$45 -> 60 | G21: =Assumptions!$B$45 -> 60 | H21: =Assumptions!$B$45 -> 60 | I21: =Assumptions!$B$45 -> 60 | ... Y21: =Assumptions!$B$45 -> 60 | Z21: =SUM(B21:Y21) -> 1440
A22: Marketing | B22: =IF(1<=6,Assumptions!$B$46,IF(1<=12,Assumptions!$B$47,Assumptions!$B$48)) -> 150 | C22: =IF(2<=6,Assumptions!$B$46,IF(2<=12,Assumptions!$B$47,Assumptions!$B$48)) -> 150 | D22: =IF(3<=6,Assumptions!$B$46,IF(3<=12,Assumptions!$B$47,Assumptions!$B$48)) -> 150 | E22: =IF(4<=6,Assumptions!$B$46,IF(4<=12,Assumptions!$B$47,Assumptions!$B$48)) -> 150 | F22: =IF(5<=6,Assumptions!$B$46,IF(5<=12,Assumptions!$B$47,Assumptions!$B$48)) -> 150 | G22: =IF(6<=6,Assumptions!$B$46,IF(6<=12,Assumptions!$B$47,Assumptions!$B$48)) -> 150 | H22: =IF(7<=6,Assumptions!$B$46,IF(7<=12,Assumptions!$B$47,Assumptions!$B$48)) -> 400 | I22: =IF(8<=6,Assumptions!$B$46,IF(8<=12,Assumptions!$B$47,Assumptions!$B$48)) -> 400 | J22: =IF(9<=6,Assumptions!$B$46,IF(9<=12,Assumptions!$B$47,Assumptions!$B$48)) -> 400 | K22: =IF(10<=6,Assumptions!$B$46,IF(10<=12,Assumptions!$B$47,Assumptions!$B$48)) -> 400 | L22: =IF(11<=6,Assumptions!$B$46,IF(11<=12,Assumptions!$B$47,Assumptions!$B$48)) -> 400 | M22: =IF(12<=6,Assumptions!$B$46,IF(12<=12,Assumptions!$B$47,Assumptions!$B$48)) -> 400 | N22: =IF(13<=6,Assumptions!$B$46,IF(13<=12,Assumptions!$B$47,Assumptions!$B$48)) -> 600 | O22: =IF(14<=6,Assumptions!$B$46,IF(14<=12,Assumptions!$B$47,Assumptions!$B$48)) -> 600 | P22: =IF(15<=6,Assumptions!$B$46,IF(15<=12,Assumptions!$B$47,Assumptions!$B$48)) -> 600 | Q22: =IF(16<=6,Assumptions!$B$46,IF(16<=12,Assumptions!$B$47,Assumptions!$B$48)) -> 600 | R22: =IF(17<=6,Assumptions!$B$46,IF(17<=12,Assumptions!$B$47,Assumptions!$B$48)) -> 600 | S22: =IF(18<=6,Assumptions!$B$46,IF(18<=12,Assumptions!$B$47,Assumptions!$B$48)) -> 600 | T22: =IF(19<=6,Assumptions!$B$46,IF(19<=12,Assumptions!$B$47,Assumptions!$B$48)) -> 600 | U22: =IF(20<=6,Assumptions!$B$46,IF(20<=12,Assumptions!$B$47,Assumptions!$B$48)) -> 600 | V22: =IF(21<=6,Assumptions!$B$46,IF(21<=12,Assumptions!$B$47,Assumptions!$B$48)) -> 600 | W22: =IF(22<=6,Assumptions!$B$46,IF(22<=12,Assumptions!$B$47,Assumptions!$B$48)) -> 600 | X22: =IF(23<=6,Assumptions!$B$46,IF(23<=12,Assumptions!$B$47,Assumptions!$B$48)) -> 600 | Y22: =IF(24<=6,Assumptions!$B$46,IF(24<=12,Assumptions!$B$47,Assumptions!$B$48)) -> 600 | Z22: =SUM(B22:Y22) -> 10500
A23: KB Maintenance + Content | B23: =IF(1>=7,Assumptions!$B$49,0) -> 0 | C23: =IF(2>=7,Assumptions!$B$49,0) -> 0 | D23: =IF(3>=7,Assumptions!$B$49,0) -> 0 | E23: =IF(4>=7,Assumptions!$B$49,0) -> 0 | F23: =IF(5>=7,Assumptions!$B$49,0) -> 0 | G23: =IF(6>=7,Assumptions!$B$49,0) -> 0 | H23: =IF(7>=7,Assumptions!$B$49,0) -> 2500 | I23: =IF(8>=7,Assumptions!$B$49,0) -> 2500 | J23: =IF(9>=7,Assumptions!$B$49,0) -> 2500 | K23: =IF(10>=7,Assumptions!$B$49,0) -> 2500 | L23: =IF(11>=7,Assumptions!$B$49,0) -> 2500 | M23: =IF(12>=7,Assumptions!$B$49,0) -> 2500 | N23: =IF(13>=7,Assumptions!$B$49,0) -> 2500 | O23: =IF(14>=7,Assumptions!$B$49,0) -> 2500 | P23: =IF(15>=7,Assumptions!$B$49,0) -> 2500 | Q23: =IF(16>=7,Assumptions!$B$49,0) -> 2500 | R23: =IF(17>=7,Assumptions!$B$49,0) -> 2500 | S23: =IF(18>=7,Assumptions!$B$49,0) -> 2500 | T23: =IF(19>=7,Assumptions!$B$49,0) -> 2500 | U23: =IF(20>=7,Assumptions!$B$49,0) -> 2500 | V23: =IF(21>=7,Assumptions!$B$49,0) -> 2500 | W23: =IF(22>=7,Assumptions!$B$49,0) -> 2500 | X23: =IF(23>=7,Assumptions!$B$49,0) -> 2500 | Y23: =IF(24>=7,Assumptions!$B$49,0) -> 2500 | Z23: =SUM(B23:Y23) -> 45000
A24: Legal/Compliance | B24: =IF(MOD(1,3)=0,Assumptions!$B$50,0) -> 0 | C24: =IF(MOD(2,3)=0,Assumptions!$B$50,0) -> 0 | D24: =IF(MOD(3,3)=0,Assumptions!$B$50,0) -> 750 | E24: =IF(MOD(4,3)=0,Assumptions!$B$50,0) -> 0 | F24: =IF(MOD(5,3)=0,Assumptions!$B$50,0) -> 0 | G24: =IF(MOD(6,3)=0,Assumptions!$B$50,0) -> 750 | H24: =IF(MOD(7,3)=0,Assumptions!$B$50,0) -> 0 | I24: =IF(MOD(8,3)=0,Assumptions!$B$50,0) -> 0 | J24: =IF(MOD(9,3)=0,Assumptions!$B$50,0) -> 750 | K24: =IF(MOD(10,3)=0,Assumptions!$B$50,0) -> 0 | L24: =IF(MOD(11,3)=0,Assumptions!$B$50,0) -> 0 | M24: =IF(MOD(12,3)=0,Assumptions!$B$50,0) -> 750 | N24: =IF(MOD(13,3)=0,Assumptions!$B$50,0) -> 0 | O24: =IF(MOD(14,3)=0,Assumptions!$B$50,0) -> 0 | P24: =IF(MOD(15,3)=0,Assumptions!$B$50,0) -> 750 | Q24: =IF(MOD(16,3)=0,Assumptions!$B$50,0) -> 0 | R24: =IF(MOD(17,3)=0,Assumptions!$B$50,0) -> 0 | S24: =IF(MOD(18,3)=0,Assumptions!$B$50,0) -> 750 | T24: =IF(MOD(19,3)=0,Assumptions!$B$50,0) -> 0 | U24: =IF(MOD(20,3)=0,Assumptions!$B$50,0) -> 0 | V24: =IF(MOD(21,3)=0,Assumptions!$B$50,0) -> 750 | W24: =IF(MOD(22,3)=0,Assumptions!$B$50,0) -> 0 | X24: =IF(MOD(23,3)=0,Assumptions!$B$50,0) -> 0 | Y24: =IF(MOD(24,3)=0,Assumptions!$B$50,0) -> 750 | Z24: =SUM(B24:Y24) -> 6000
A25: Founder Salary | B25: =IF(1<=6,Assumptions!$B$53,IF(1<=12,Assumptions!$B$54,Assumptions!$B$55)) -> 2000 | C25: =IF(2<=6,Assumptions!$B$53,IF(2<=12,Assumptions!$B$54,Assumptions!$B$55)) -> 2000 | D25: =IF(3<=6,Assumptions!$B$53,IF(3<=12,Assumptions!$B$54,Assumptions!$B$55)) -> 2000 | E25: =IF(4<=6,Assumptions!$B$53,IF(4<=12,Assumptions!$B$54,Assumptions!$B$55)) -> 2000 | F25: =IF(5<=6,Assumptions!$B$53,IF(5<=12,Assumptions!$B$54,Assumptions!$B$55)) -> 2000 | G25: =IF(6<=6,Assumptions!$B$53,IF(6<=12,Assumptions!$B$54,Assumptions!$B$55)) -> 2000 | H25: =IF(7<=6,Assumptions!$B$53,IF(7<=12,Assumptions!$B$54,Assumptions!$B$55)) -> 3000 | I25: =IF(8<=6,Assumptions!$B$53,IF(8<=12,Assumptions!$B$54,Assumptions!$B$55)) -> 3000 | J25: =IF(9<=6,Assumptions!$B$53,IF(9<=12,Assumptions!$B$54,Assumptions!$B$55)) -> 3000 | K25: =IF(10<=6,Assumptions!$B$53,IF(10<=12,Assumptions!$B$54,Assumptions!$B$55)) -> 3000 | L25: =IF(11<=6,Assumptions!$B$53,IF(11<=12,Assumptions!$B$54,Assumptions!$B$55)) -> 3000 | M25: =IF(12<=6,Assumptions!$B$53,IF(12<=12,Assumptions!$B$54,Assumptions!$B$55)) -> 3000 | N25: =IF(13<=6,Assumptions!$B$53,IF(13<=12,Assumptions!$B$54,Assumptions!$B$55)) -> 4000 | O25: =IF(14<=6,Assumptions!$B$53,IF(14<=12,Assumptions!$B$54,Assumptions!$B$55)) -> 4000 | P25: =IF(15<=6,Assumptions!$B$53,IF(15<=12,Assumptions!$B$54,Assumptions!$B$55)) -> 4000 | Q25: =IF(16<=6,Assumptions!$B$53,IF(16<=12,Assumptions!$B$54,Assumptions!$B$55)) -> 4000 | R25: =IF(17<=6,Assumptions!$B$53,IF(17<=12,Assumptions!$B$54,Assumptions!$B$55)) -> 4000 | S25: =IF(18<=6,Assumptions!$B$53,IF(18<=12,Assumptions!$B$54,Assumptions!$B$55)) -> 4000 | T25: =IF(19<=6,Assumptions!$B$53,IF(19<=12,Assumptions!$B$54,Assumptions!$B$55)) -> 4000 | U25: =IF(20<=6,Assumptions!$B$53,IF(20<=12,Assumptions!$B$54,Assumptions!$B$55)) -> 4000 | V25: =IF(21<=6,Assumptions!$B$53,IF(21<=12,Assumptions!$B$54,Assumptions!$B$55)) -> 4000 | W25: =IF(22<=6,Assumptions!$B$53,IF(22<=12,Assumptions!$B$54,Assumptions!$B$55)) -> 4000 | X25: =IF(23<=6,Assumptions!$B$53,IF(23<=12,Assumptions!$B$54,Assumptions!$B$55)) -> 4000 | Y25: =IF(24<=6,Assumptions!$B$53,IF(24<=12,Assumptions!$B$54,Assumptions!$B$55)) -> 4000 | Z25: =SUM(B25:Y25) -> 78000
A26: TOTAL COSTS | B26: =B18+B19+B20+B21+B22+B23+B24+B25 -> 2290 | C26: =C18+C19+C20+C21+C22+C23+C24+C25 -> 2296 | D26: =D18+D19+D20+D21+D22+D23+D24+D25 -> 3053 | E26: =E18+E19+E20+E21+E22+E23+E24+E25 -> 2311 | F26: =F18+F19+F20+F21+F22+F23+F24+F25 -> 2322 | G26: =G18+G19+G20+G21+G22+G23+G24+G25 -> 3083 | H26: =H18+H19+H20+H21+H22+H23+H24+H25 -> 6090 | I26: =I18+I19+I20+I21+I22+I23+I24+I25 -> 6099 | ... Y26: =Y18+Y19+Y20+Y21+Y22+Y23+Y24+Y25 -> 8266 | Z26: =SUM(B26:Y26) -> 145855
A28: PROFITABILITY
A29: NET INCOME (incl founder comp) | B29: =B15-B26 -> -2253 | C29: =C15-C26 -> -2209 | D29: =D15-D26 -> -2786 | E29: =E15-E26 -> -1943 | F29: =F15-F26 -> -1879 | G29: =G15-G26 -> -2513 | H29: =H15-H26 -> -5419 | I29: =I15-I26 -> -5314 | ... Y29: =Y15-Y26 -> -3455 | Z29: =SUM(B29:Y29) -> -93211
A30: Gross Margin % | B30: =IF(B15=0,0,(B15-(B18+B19+B20))/B15) -> -1.1621622 | C30: =IF(C15=0,0,(C15-(C18+C19+C20))/C15) -> 0.011494253 | D30: =IF(D15=0,0,(D15-(D18+D19+D20))/D15) -> 0.65168539 | E30: =IF(E15=0,0,(E15-(E18+E19+E20))/E15) -> 0.72554348 | F30: =IF(F15=0,0,(F15-(F18+F19+F20))/F15) -> 0.74717833 | G30: =IF(G15=0,0,(G15-(G18+G19+G20))/G15) -> 0.78421053 | H30: =IF(H15=0,0,(H15-(H18+H19+H20))/H15) -> 0.80625931 | I30: =IF(I15=0,0,(I15-(I18+I19+I20))/I15) -> 0.82292994 | ... Y30: =IF(Y15=0,0,(Y15-(Y18+Y19+Y20))/Y15) -> 0.92600291 | Z30: =AVERAGE(B30:Y30) -> 0.74846547
A31: Cumulative P&L | B31: =B29 -> -2253 | C31: =B31+C29 -> -4462 | D31: =C31+D29 -> -7248 | E31: =D31+E29 -> -9191 | F31: =E31+F29 -> -11070 | G31: =F31+G29 -> -13583 | H31: =G31+H29 -> -19002 | I31: =H31+I29 -> -24316 | J31: =I31+J29 -> -30182 | ... Y31: =X31+Y29 -> -93211 | Z31: =Y31 -> -93211

Sheet Formulas
A1: WAYPOINT MODEL FORMULAS REFERENCE
A2: All revenue and cost rows in Monthly P&L are formula-driven from the Assumptions tab.
A3: Change any blue input on Assumptions tab → P&L auto-updates.
A5: Line Item | B5: Formula | C5: Notes
B6: SUBSCRIBER METRICS (NOW FORMULA-DRIVEN FROM ASSUMPTIONS)
A7: New Paid Subscribers | B7: =MIN(MAX(ROUND(BASE_NEW*(1+GrowthRate)^(mo-1)),BASE_NEW),50) | C7: NOW FORMULA. Growth rate = IF(mo<=6,G16,IF(mo<=12,G712,IF(mo<=18,G1318,G1924)))
A8: Churned Subscribers | B8: =ROUND(PrevMonth_TotalSubs * CHURN, 0) | C8: NOW FORMULA referencing Assumptions!CHURN
A9: Total Paid Subscribers | B9: =IF(raw < CAP*0.5, raw, MIN(raw, CAP)) where raw = prev + new - churned | C9: NOW FORMULA with soft cap from Assumptions!SUB_CAP
A10: RC Reimbursed Users | B10: =IF(Mo<RC_START,0,IF(Mo=RC_START,RC_INIT, prev+ROUND(prev*RC_GROW_PCT)-ROUND(prev*RC_CHURN))) | C10: NOW FORMULA. Pct-based growth like consumer subs, starts at RC_START
A11: IEPClarity New Purchases | B11: =IF(Mo<IEP_START,0,MIN(MAX(1,ROUND(IEP_BASE*(1+IEP_GROW)^(Mo-IEP_START))),25)) | C11: NOW FORMULA referencing Assumptions
A12: B2B Provider Listings | B12: =IF(Mo<B2B_START,0,MIN(B2B_INIT+(Mo-B2B_START)*B2B_GROW,30)) | C12: NOW FORMULA referencing Assumptions
B14: REVENUE (formula-driven from Assumptions)
A15: Consumer Subscription Revenue | B15: =ROUND(totalsubs * (nav_price*(1-pro_pct) + pro_price*pro_pct), 0) | C15: Blended ARPU from Nav + Pro mix
A16: RC Reimbursement Revenue | B16: =RC_Users * RC_RATE (where RC_RATE = blended ARPU, same as consumer) | C16: RC pays same ARPU as consumer. Family pays $0.
A17: IEPClarity Revenue | B17: =iep_newpurchases * iep_avg | C17: One-time purchases, clean monthly
A18: B2B Directory Revenue | B18: =b2b_listings * b2b_rate
A19: TOTAL REVENUE | B19: =SUM(consumersub + rc + iep + b2b)
B21: COSTS (formula-driven from Assumptions)
A22: AI API Costs | B22: =ROUND((totalsubs + rc_users) * api_cost, 0) | C22: All active users consume API
A23: Infrastructure | B23: =ROUND(infra_base + (totalsubs + rc_users) * infra_per, 0) | C23: Base + per-user scaling
A24: SMS Costs | B24: =ROUND((totalsubs + rc_users) * sms_per, 0)
A25: Domain + SaaS Tools | B25: =domain | C25: Flat monthly
A26: Marketing | B26: =IF(mo<=6, mktg_1_6, IF(mo<=12, mktg_7_12, mktg_13_24)) | C26: Tiered by growth phase
A27: KB Maintenance + Content | B27: =IF(mo>=7, kb_content, 0) | C27: Starts Month 7
A28: Legal/Compliance | B28: =IF(MOD(month,3)=0, legal, 0) | C28: Quarterly
A29: Founder Salary | B29: =IF(mo<=6, salary_1_6, IF(mo<=12, salary_7_12, salary_13_24)) | C29: Tiered; change on Assumptions tab
A30: TOTAL COSTS | B30: =SUM(all cost rows)
B32: PROFITABILITY
A33: NET INCOME | B33: =total_revenue - total_costs | C33: Includes founder comp
A34: Gross Margin % | B34: =IF(revenue=0, 0, (revenue - api - infra - sms) / revenue) | C34: COGS = variable costs only
A35: Cumulative P&L | B35: =prevmonth_cumulative + thismonth_netincome | C35: Running total
B37: LOGISTIC CAP FUNCTION (Python-computed)
A38: logistic_cap(raw, cap) | B38: if raw <= cap*0.5: return raw # no effect below 50% of cap | C38: Soft ceiling, not hard cutoff
B39: else: excess = raw - cap*0.5; remaining = cap*0.5
B40: compressed = remaining * (1 - exp(-2*excess/remaining))
B41: return min(int(cap*0.5 + compressed), cap) | C41: At default 400, no effect until ~200 subs

Sheet Unit Economics
A1: WAYPOINT UNIT ECONOMICS
A3: Metric | B3: Consumer (Nav) | C3: Consumer (Pro) | D3: RC Reimbursed | E3: Notes
A4: Monthly Revenue / User | B4: $9.99 | C4: $19.99 | D4: $100.00
A5: AI API Cost / User / Mo | B5: $1.25 | C5: $1.75 | D5: $1.25 | E5: Conservative buffer
A6: Infrastructure / User / Mo | B6: $0.20 | C6: $0.25 | D6: $0.20
A7: SMS / User / Mo | B7: $0.12 | C7: $0.12 | D7: $0.12
A8: Total Variable Cost / User / Mo | B8: $1.57 | C8: $2.12 | D8: $1.57
A9: Gross Profit / User / Mo | B9: $8.42 | C9: $17.87 | D9: $98.43
A10: Gross Margin | B10: 84.3% | C10: 89.4% | D10: 98.4%
A12: Customer Acquisition Cost (CAC) | B12: $20-40 | C12: $20-40 | D12: ~$0 | E12: Conservative
A13: Monthly Churn Rate | B13: 7.0% | C13: 5.0% | D13: 3.0% | E13: 7% pre-PMF
A14: Avg Customer Lifetime (months) | B14: 14 | C14: 20 | D14: 33
A15: Lifetime Value (LTV) | B15: $118 | C15: $357 | D15: $3,248
A16: LTV / CAC Ratio | B16: 3-6x | C16: 9-18x | D16: ∞
A18: Months to Recover CAC | B18: 2-5 | C18: 1-2 | D18: 0

Sheet Scenario Analysis
A1: SCENARIO ANALYSIS — INCLUDES FOUNDER COMP
A2: All scenarios include founder salary. Default = Conservative.
A4: Metric | B4: Conservative (DEFAULT) | C4: Base Case | D4: Optimistic | E4: Key Driver
B5: 24-MONTH OUTCOMES (incl founder salary)
A6: Paid subscribers (Mo 24) | B6: 145 | C6: 300 | D6: 700
A7: RC reimbursed users (Mo 24) | B7: 80 | C7: 125 | D7: 200
A8: Monthly revenue (Mo 24) | B8: $12,386 | C8: $18,000 | D8: $40,000
A9: Annual run rate (Mo 24) | B9: $148,632 | C9: $216,000 | D9: $480,000
A11: 24-mo total revenue | B11: $116,171 | C11: $120,000 | D11: $280,000
A12: 24-mo total costs (incl salary) | B12: $146,492 | C12: $130,000 | D12: $150,000 | E12: Salary + KB = major line items
A13: 24-mo net income | B13: $-30,321 | C13: ($10,000) | D13: $130,000 | E13: Conservative case negative w/ salary
A14: Max cash needed (trough) | B14: $48,000 | C14: $18,000 | D14: $8,000 | E14: Personal investment required
B16: BREAKEVEN (honest, with founder comp)
A17: Month of first profitability | B17: Month 16-18 | C17: Month 14 | D17: Month 6 | E17: Salary pushes breakeven later
A18: Personal investment needed | B18: $45-50K | C18: $15-18K | D18: $5-8K | E18: All scenarios need seed cash
A19: External funding needed? | B19: No | C19: No | D19: No | E19: Bootstrappable with personal funds

Sheet Cash Flow Summary
B1: Q1 2026 (Mar-May) | C1: Q2 2026 (Jun-Aug) | D1: Q3 2026 (Sep-Nov) | E1: Q4 2026 (Dec-Feb) | F1: Q1 2027 (Mar-May) | G1: Q2 2027 (Jun-Aug) | H1: Q3 2027 (Sep-Nov) | I1: Q4 2027 (Dec-Feb) | J1: 24-Mo Total
A2: QUARTERLY SUMMARY (formula-driven from Monthly P&L)
A3: Paid Subscribers (end) | B3: ='Monthly P&L'!D5 -> 12 | C3: ='Monthly P&L'!G5 -> 30 | D3: ='Monthly P&L'!J5 -> 47 | E3: ='Monthly P&L'!M5 -> 73 | F3: ='Monthly P&L'!P5 -> 87 | G3: ='Monthly P&L'!S5 -> 109 | H3: ='Monthly P&L'!V5 -> 124 | I3: ='Monthly P&L'!Y5 -> 145 | J3: =I3 -> 145
A4: RC Users (end) | B4: ='Monthly P&L'!D6 -> 0 | C4: ='Monthly P&L'!G6 -> 0 | D4: ='Monthly P&L'!J6 -> 5 | E4: ='Monthly P&L'!M6 -> 8 | F4: ='Monthly P&L'!P6 -> 12 | G4: ='Monthly P&L'!S6 -> 18 | H4: ='Monthly P&L'!V6 -> 24 | I4: ='Monthly P&L'!Y6 -> 34 | J4: =I4 -> 34
A5: Total Users (end) | B5: ='Monthly P&L'!D5+'Monthly P&L'!D6 -> 12 | C5: ='Monthly P&L'!G5+'Monthly P&L'!G6 -> 30 | D5: ='Monthly P&L'!J5+'Monthly P&L'!J6 -> 52 | E5: ='Monthly P&L'!M5+'Monthly P&L'!M6 -> 81 | F5: ='Monthly P&L'!P5+'Monthly P&L'!P6 -> 99 | G5: ='Monthly P&L'!S5+'Monthly P&L'!S6 -> 127 | H5: ='Monthly P&L'!V5+'Monthly P&L'!V6 -> 148 | I5: ='Monthly P&L'!Y5+'Monthly P&L'!Y6 -> 179 | J5: =I5 -> 179
A7: Consumer Subscription Revenue | B7: =SUM('Monthly P&L'!B11:D11) -> 274 | C7: =SUM('Monthly P&L'!E11:G11) -> 874 | D7: =SUM('Monthly P&L'!H11:J11) -> 1536 | E7: =SUM('Monthly P&L'!K11:M11) -> 2386 | F7: =SUM('Monthly P&L'!N11:P11) -> 3073 | G7: =SUM('Monthly P&L'!Q11:S11) -> 3796 | H7: =SUM('Monthly P&L'!T11:V11) -> 4434 | I7: =SUM('Monthly P&L'!W11:Y11) -> 5146 | J7: =SUM(B7:I7) -> 21519
A8: RC Reimbursement Revenue | B8: =SUM('Monthly P&L'!B12:D12) -> 0 | C8: =SUM('Monthly P&L'!E12:G12) -> 0 | D8: =SUM('Monthly P&L'!H12:J12) -> 62 | E8: =SUM('Monthly P&L'!K12:M12) -> 262 | F8: =SUM('Monthly P&L'!N12:P12) -> 387 | G8: =SUM('Monthly P&L'!Q12:S12) -> 600 | H8: =SUM('Monthly P&L'!T12:V12) -> 825 | I8: =SUM('Monthly P&L'!W12:Y12) -> 1137 | J8: =SUM(B8:I8) -> 3273
A9: IEPClarity Revenue | B9: =SUM('Monthly P&L'!B13:D13) -> 117 | C9: =SUM('Monthly P&L'!E13:G13) -> 507 | D9: =SUM('Monthly P&L'!H13:J13) -> 858 | E9: =SUM('Monthly P&L'!K13:M13) -> 1521 | F9: =SUM('Monthly P&L'!N13:P13) -> 2574 | G9: =SUM('Monthly P&L'!Q13:S13) -> 2925 | H9: =SUM('Monthly P&L'!T13:V13) -> 2925 | I9: =SUM('Monthly P&L'!W13:Y13) -> 2925 | J9: =SUM(B9:I9) -> 14352
A10: B2B Directory Revenue | B10: =SUM('Monthly P&L'!B14:D14) -> 0 | C10: =SUM('Monthly P&L'!E14:G14) -> 0 | D10: =SUM('Monthly P&L'!H14:J14) -> 0 | E10: =SUM('Monthly P&L'!K14:M14) -> 900 | F10: =SUM('Monthly P&L'!N14:P14) -> 1800 | G10: =SUM('Monthly P&L'!Q14:S14) -> 2700 | H10: =SUM('Monthly P&L'!T14:V14) -> 3600 | I10: =SUM('Monthly P&L'!W14:Y14) -> 4500 | J10: =SUM(B10:I10) -> 13500
A11: QUARTERLY REVENUE | B11: =SUM('Monthly P&L'!B15:D15) -> 391 | C11: =SUM('Monthly P&L'!E15:G15) -> 1381 | D11: =SUM('Monthly P&L'!H15:J15) -> 2456 | E11: =SUM('Monthly P&L'!K15:M15) -> 5069 | F11: =SUM('Monthly P&L'!N15:P15) -> 7834 | G11: =SUM('Monthly P&L'!Q15:S15) -> 10021 | H11: =SUM('Monthly P&L'!T15:V15) -> 11784 | I11: =SUM('Monthly P&L'!W15:Y15) -> 13708 | J11: =SUM(B11:I11) -> 52644
A13: AI API Costs | B13: =SUM('Monthly P&L'!B18:D18) -> 28 | C13: =SUM('Monthly P&L'!E18:G18) -> 88 | D13: =SUM('Monthly P&L'!H18:J18) -> 160 | E13: =SUM('Monthly P&L'!K18:M18) -> 265 | F13: =SUM('Monthly P&L'!N18:P18) -> 347 | G13: =SUM('Monthly P&L'!Q18:S18) -> 440 | H13: =SUM('Monthly P&L'!T18:V18) -> 526 | I13: =SUM('Monthly P&L'!W18:Y18) -> 629 | J13: =SUM(B13:I13) -> 2483
A14: Infrastructure | B14: =SUM('Monthly P&L'!B19:D19) -> 229 | C14: =SUM('Monthly P&L'!E19:G19) -> 239 | D14: =SUM('Monthly P&L'!H19:J19) -> 250 | E14: =SUM('Monthly P&L'!K19:M19) -> 267 | F14: =SUM('Monthly P&L'!N19:P19) -> 280 | G14: =SUM('Monthly P&L'!Q19:S19) -> 295 | H14: =SUM('Monthly P&L'!T19:V19) -> 310 | I14: =SUM('Monthly P&L'!W19:Y19) -> 325 | J14: =SUM(B14:I14) -> 2195
A15: SMS Costs | B15: =SUM('Monthly P&L'!B20:D20) -> 2 | C15: =SUM('Monthly P&L'!E20:G20) -> 9 | D15: =SUM('Monthly P&L'!H20:J20) -> 15 | E15: =SUM('Monthly P&L'!K20:M20) -> 25 | F15: =SUM('Monthly P&L'!N20:P20) -> 33 | G15: =SUM('Monthly P&L'!Q20:S20) -> 42 | H15: =SUM('Monthly P&L'!T20:V20) -> 51 | I15: =SUM('Monthly P&L'!W20:Y20) -> 60 | J15: =SUM(B15:I15) -> 237
A16: Domain + SaaS | B16: =SUM('Monthly P&L'!B21:D21) -> 180 | C16: =SUM('Monthly P&L'!E21:G21) -> 180 | D16: =SUM('Monthly P&L'!H21:J21) -> 180 | E16: =SUM('Monthly P&L'!K21:M21) -> 180 | F16: =SUM('Monthly P&L'!N21:P21) -> 180 | G16: =SUM('Monthly P&L'!Q21:S21) -> 180 | H16: =SUM('Monthly P&L'!T21:V21) -> 180 | I16: =SUM('Monthly P&L'!W21:Y21) -> 180 | J16: =SUM(B16:I16) -> 1440
A17: Marketing | B17: =SUM('Monthly P&L'!B22:D22) -> 450 | C17: =SUM('Monthly P&L'!E22:G22) -> 450 | D17: =SUM('Monthly P&L'!H22:J22) -> 1200 | E17: =SUM('Monthly P&L'!K22:M22) -> 1200 | F17: =SUM('Monthly P&L'!N22:P22) -> 1800 | G17: =SUM('Monthly P&L'!Q22:S22) -> 1800 | H17: =SUM('Monthly P&L'!T22:V22) -> 1800 | I17: =SUM('Monthly P&L'!W22:Y22) -> 1800 | J17: =SUM(B17:I17) -> 10500
A18: KB Maintenance + Content | B18: =SUM('Monthly P&L'!B23:D23) -> 0 | C18: =SUM('Monthly P&L'!E23:G23) -> 0 | D18: =SUM('Monthly P&L'!H23:J23) -> 7500 | E18: =SUM('Monthly P&L'!K23:M23) -> 7500 | F18: =SUM('Monthly P&L'!N23:P23) -> 7500 | G18: =SUM('Monthly P&L'!Q23:S23) -> 7500 | H18: =SUM('Monthly P&L'!T23:V23) -> 7500 | I18: =SUM('Monthly P&L'!W23:Y23) -> 7500 | J18: =SUM(B18:I18) -> 45000
A19: Legal/Compliance | B19: =SUM('Monthly P&L'!B24:D24) -> 750 | C19: =SUM('Monthly P&L'!E24:G24) -> 750 | D19: =SUM('Monthly P&L'!H24:J24) -> 750 | E19: =SUM('Monthly P&L'!K24:M24) -> 750 | F19: =SUM('Monthly P&L'!N24:P24) -> 750 | G19: =SUM('Monthly P&L'!Q24:S24) -> 750 | H19: =SUM('Monthly P&L'!T24:V24) -> 750 | I19: =SUM('Monthly P&L'!W24:Y24) -> 750 | J19: =SUM(B19:I19) -> 6000
A20: Founder Salary | B20: =SUM('Monthly P&L'!B25:D25) -> 6000 | C20: =SUM('Monthly P&L'!E25:G25) -> 6000 | D20: =SUM('Monthly P&L'!H25:J25) -> 9000 | E20: =SUM('Monthly P&L'!K25:M25) -> 9000 | F20: =SUM('Monthly P&L'!N25:P25) -> 12000 | G20: =SUM('Monthly P&L'!Q25:S25) -> 12000 | H20: =SUM('Monthly P&L'!T25:V25) -> 12000 | I20: =SUM('Monthly P&L'!W25:Y25) -> 12000 | J20: =SUM(B20:I20) -> 78000
A21: QUARTERLY COSTS | B21: =SUM('Monthly P&L'!B26:D26) -> 7639 | C21: =SUM('Monthly P&L'!E26:G26) -> 7716 | D21: =SUM('Monthly P&L'!H26:J26) -> 19055 | E21: =SUM('Monthly P&L'!K26:M26) -> 19187 | F21: =SUM('Monthly P&L'!N26:P26) -> 22890 | G21: =SUM('Monthly P&L'!Q26:S26) -> 23007 | H21: =SUM('Monthly P&L'!T26:V26) -> 23117 | I21: =SUM('Monthly P&L'!W26:Y26) -> 23244 | J21: =SUM(B21:I21) -> 145855
A23: QUARTERLY NET INCOME | B23: =SUM('Monthly P&L'!B29:D29) -> -7248 | C23: =SUM('Monthly P&L'!E29:G29) -> -6335 | D23: =SUM('Monthly P&L'!H29:J29) -> -16599 | E23: =SUM('Monthly P&L'!K29:M29) -> -14118 | F23: =SUM('Monthly P&L'!N29:P29) -> -15056 | G23: =SUM('Monthly P&L'!Q29:S29) -> -12986 | H23: =SUM('Monthly P&L'!T29:V29) -> -11333 | I23: =SUM('Monthly P&L'!W29:Y29) -> -9536 | J23: =SUM(B23:I23) -> -93211
A24: Cumulative Net Income | B24: ='Monthly P&L'!D31 -> -7248 | C24: ='Monthly P&L'!G31 -> -13583 | D24: ='Monthly P&L'!J31 -> -30182 | E24: ='Monthly P&L'!M31 -> -44300 | F24: ='Monthly P&L'!P31 -> -59356 | G24: ='Monthly P&L'!S31 -> -72342 | H24: ='Monthly P&L'!V31 -> -83675 | I24: ='Monthly P&L'!Y31 -> -93211 | J24: =I24 -> -93211
A25: Avg Gross Margin % | B25: =AVERAGE('Monthly P&L'!B30:D30) -> -0.16632751 | C25: =AVERAGE('Monthly P&L'!E30:G30) -> 0.75231078 | D25: =AVERAGE('Monthly P&L'!H30:J30) -> 0.82439642 | E25: =AVERAGE('Monthly P&L'!K30:M30) -> 0.88886017 | F25: =AVERAGE('Monthly P&L'!N30:P30) -> 0.91531858 | G25: =AVERAGE('Monthly P&L'!Q30:S30) -> 0.9224307 | H25: =AVERAGE('Monthly P&L'!T30:V30) -> 0.92470657 | I25: =AVERAGE('Monthly P&L'!W30:Y30) -> 0.92602808 | J25: =AVERAGE(B25:I25) -> 0.74846547
A27: CASH POSITION ANALYSIS
A28: Cash Needed (if cum < 0) | B28: =MAX(0,-B24) -> 7248 | C28: =MAX(0,-C24) -> 13583 | D28: =MAX(0,-D24) -> 30182 | E28: =MAX(0,-E24) -> 44300 | F28: =MAX(0,-F24) -> 59356 | G28: =MAX(0,-G24) -> 72342 | H28: =MAX(0,-H24) -> 83675 | I28: =MAX(0,-I24) -> 93211 | J28: =MAX(B28:I28) -> 93211
A29: Quarter Profitable? | B29: =IF(B23>0,"YES","NO") -> NO | C29: =IF(C23>0,"YES","NO") -> NO | D29: =IF(D23>0,"YES","NO") -> NO | E29: =IF(E23>0,"YES","NO") -> NO | F29: =IF(F23>0,"YES","NO") -> NO | G29: =IF(G23>0,"YES","NO") -> NO | H29: =IF(H23>0,"YES","NO") -> NO | I29: =IF(I23>0,"YES","NO") -> NO
A31: REVENUE MIX (% of quarterly total)
A32: Consumer Subscription % | B32: =IF(B11=0,0,SUM('Monthly P&L'!B11:D11)/B11) -> 0.70076726 | C32: =IF(C11=0,0,SUM('Monthly P&L'!E11:G11)/C11) -> 0.63287473 | D32: =IF(D11=0,0,SUM('Monthly P&L'!H11:J11)/D11) -> 0.62540717 | E32: =IF(E11=0,0,SUM('Monthly P&L'!K11:M11)/E11) -> 0.47070428 | F32: =IF(F11=0,0,SUM('Monthly P&L'!N11:P11)/F11) -> 0.39226449 | G32: =IF(G11=0,0,SUM('Monthly P&L'!Q11:S11)/G11) -> 0.37880451 | H32: =IF(H11=0,0,SUM('Monthly P&L'!T11:V11)/H11) -> 0.37627291 | I32: =IF(I11=0,0,SUM('Monthly P&L'!W11:Y11)/I11) -> 0.37540123 | J32: =IF(J11=0,0,SUM('Monthly P&L'!B11:Y11)/J11) -> 0.40876453
A33: RC Reimbursement % | B33: =IF(B11=0,0,SUM('Monthly P&L'!B12:D12)/B11) -> 0 | C33: =IF(C11=0,0,SUM('Monthly P&L'!E12:G12)/C11) -> 0 | D33: =IF(D11=0,0,SUM('Monthly P&L'!H12:J12)/D11) -> 0.0252443 | E33: =IF(E11=0,0,SUM('Monthly P&L'!K12:M12)/E11) -> 0.051686723 | F33: =IF(F11=0,0,SUM('Monthly P&L'!N12:P12)/F11) -> 0.049400051 | G33: =IF(G11=0,0,SUM('Monthly P&L'!Q12:S12)/G11) -> 0.059874264 | H33: =IF(H11=0,0,SUM('Monthly P&L'!T12:V12)/H11) -> 0.070010183 | I33: =IF(I11=0,0,SUM('Monthly P&L'!W12:Y12)/I11) -> 0.082944266 | J33: =IF(J11=0,0,SUM('Monthly P&L'!B12:Y12)/J11) -> 0.062172327
A34: IEPClarity % | B34: =IF(B11=0,0,SUM('Monthly P&L'!B13:D13)/B11) -> 0.29923274 | C34: =IF(C11=0,0,SUM('Monthly P&L'!E13:G13)/C11) -> 0.36712527 | D34: =IF(D11=0,0,SUM('Monthly P&L'!H13:J13)/D11) -> 0.34934853 | E34: =IF(E11=0,0,SUM('Monthly P&L'!K13:M13)/E11) -> 0.30005918 | F34: =IF(F11=0,0,SUM('Monthly P&L'!N13:P13)/F11) -> 0.32856778 | G34: =IF(G11=0,0,SUM('Monthly P&L'!Q13:S13)/G11) -> 0.29188704 | H34: =IF(H11=0,0,SUM('Monthly P&L'!T13:V13)/H11) -> 0.24821792 | I34: =IF(I11=0,0,SUM('Monthly P&L'!W13:Y13)/I11) -> 0.21337905 | J34: =IF(J11=0,0,SUM('Monthly P&L'!B13:Y13)/J11) -> 0.27262366
A35: B2B Directory % | B35: =IF(B11=0,0,SUM('Monthly P&L'!B14:D14)/B11) -> 0 | C35: =IF(C11=0,0,SUM('Monthly P&L'!E14:G14)/C11) -> 0 | D35: =IF(D11=0,0,SUM('Monthly P&L'!H14:J14)/D11) -> 0 | E35: =IF(E11=0,0,SUM('Monthly P&L'!K14:M14)/E11) -> 0.17754981 | F35: =IF(F11=0,0,SUM('Monthly P&L'!N14:P14)/F11) -> 0.22976768 | G35: =IF(G11=0,0,SUM('Monthly P&L'!Q14:S14)/G11) -> 0.26943419 | H35: =IF(H11=0,0,SUM('Monthly P&L'!T14:V14)/H11) -> 0.30549898 | I35: =IF(I11=0,0,SUM('Monthly P&L'!W14:Y14)/I11) -> 0.32827546 | J35: =IF(J11=0,0,SUM('Monthly P&L'!B14:Y14)/J11) -> 0.25643948
A37: COST STRUCTURE (% of quarterly total)
A38: Variable Costs % | B38: =IF(B21=0,0,(SUM('Monthly P&L'!B18:D18)+SUM('Monthly P&L'!B19:D19)+SUM('Monthly P&L'!B20:D20))/B21) -> 0.033904961 | C38: =IF(C21=0,0,(SUM('Monthly P&L'!E18:G18)+SUM('Monthly P&L'!E19:G19)+SUM('Monthly P&L'!E20:G20))/C21) -> 0.043545879 | D38: =IF(D21=0,0,(SUM('Monthly P&L'!H18:J18)+SUM('Monthly P&L'!H19:J19)+SUM('Monthly P&L'!H20:J20))/D21) -> 0.022303857 | E38: =IF(E21=0,0,(SUM('Monthly P&L'!K18:M18)+SUM('Monthly P&L'!K19:M19)+SUM('Monthly P&L'!K20:M20))/E21) -> 0.029030072 | F38: =IF(F21=0,0,(SUM('Monthly P&L'!N18:P18)+SUM('Monthly P&L'!N19:P19)+SUM('Monthly P&L'!N20:P20))/F21) -> 0.028833552 | G38: =IF(G21=0,0,(SUM('Monthly P&L'!Q18:S18)+SUM('Monthly P&L'!Q19:S19)+SUM('Monthly P&L'!Q20:S20))/G21) -> 0.03377233 | H38: =IF(H21=0,0,(SUM('Monthly P&L'!T18:V18)+SUM('Monthly P&L'!T19:V19)+SUM('Monthly P&L'!T20:V20))/H21) -> 0.038370031 | I38: =IF(I21=0,0,(SUM('Monthly P&L'!W18:Y18)+SUM('Monthly P&L'!W19:Y19)+SUM('Monthly P&L'!W20:Y20))/I21) -> 0.043624161 | J38: =IF(J21=0,0,(SUM('Monthly P&L'!B18:Y18)+SUM('Monthly P&L'!B19:Y19)+SUM('Monthly P&L'!B20:Y20))/J21) -> 0.033697851
A39: Founder Salary % | B39: =IF(B21=0,0,SUM('Monthly P&L'!B25:D25)/B21) -> 0.78544312 | C39: =IF(C21=0,0,SUM('Monthly P&L'!E25:G25)/C21) -> 0.77760498 | D39: =IF(D21=0,0,SUM('Monthly P&L'!H25:J25)/D21) -> 0.47231698 | E39: =IF(E21=0,0,SUM('Monthly P&L'!K25:M25)/E21) -> 0.4690676 | F39: =IF(F21=0,0,SUM('Monthly P&L'!N25:P25)/F21) -> 0.5242464 | G39: =IF(G21=0,0,SUM('Monthly P&L'!Q25:S25)/G21) -> 0.52158039 | H39: =IF(H21=0,0,SUM('Monthly P&L'!T25:V25)/H21) -> 0.5190985 | I39: =IF(I21=0,0,SUM('Monthly P&L'!W25:Y25)/I21) -> 0.51626226 | J39: =IF(J21=0,0,SUM('Monthly P&L'!B25:Y25)/J21) -> 0.53477769
A40: KB + Content % | B40: =IF(B21=0,0,SUM('Monthly P&L'!B23:D23)/B21) -> 0 | C40: =IF(C21=0,0,SUM('Monthly P&L'!E23:G23)/C21) -> 0 | D40: =IF(D21=0,0,SUM('Monthly P&L'!H23:J23)/D21) -> 0.39359748 | E40: =IF(E21=0,0,SUM('Monthly P&L'!K23:M23)/E21) -> 0.39088966 | F40: =IF(F21=0,0,SUM('Monthly P&L'!N23:P23)/F21) -> 0.327654 | G40: =IF(G21=0,0,SUM('Monthly P&L'!Q23:S23)/G21) -> 0.32598774 | H40: =IF(H21=0,0,SUM('Monthly P&L'!T23:V23)/H21) -> 0.32443656 | I40: =IF(I21=0,0,SUM('Monthly P&L'!W23:Y23)/I21) -> 0.32266391 | J40: =IF(J21=0,0,SUM('Monthly P&L'!B23:Y23)/J21) -> 0.30852559
A41: Marketing % | B41: =IF(B21=0,0,SUM('Monthly P&L'!B22:D22)/B21) -> 0.058908234 | C41: =IF(C21=0,0,SUM('Monthly P&L'!E22:G22)/C21) -> 0.058320373 | D41: =IF(D21=0,0,SUM('Monthly P&L'!H22:J22)/D21) -> 0.062975597 | E41: =IF(E21=0,0,SUM('Monthly P&L'!K22:M22)/E21) -> 0.062542346 | F41: =IF(F21=0,0,SUM('Monthly P&L'!N22:P22)/F21) -> 0.078636959 | G41: =IF(G21=0,0,SUM('Monthly P&L'!Q22:S22)/G21) -> 0.078237058 | H41: =IF(H21=0,0,SUM('Monthly P&L'!T22:V22)/H21) -> 0.077864775 | I41: =IF(I21=0,0,SUM('Monthly P&L'!W22:Y22)/I21) -> 0.077439339 | J41: =IF(J21=0,0,SUM('Monthly P&L'!B22:Y22)/J21) -> 0.071989304
A42: Other Fixed % | B42: =IF(B21=0,0,(SUM('Monthly P&L'!B21:D21)+SUM('Monthly P&L'!B24:D24))/B21) -> 0.12174368 | C42: =IF(C21=0,0,(SUM('Monthly P&L'!E21:G21)+SUM('Monthly P&L'!E24:G24))/C21) -> 0.12052877 | D42: =IF(D21=0,0,(SUM('Monthly P&L'!H21:J21)+SUM('Monthly P&L'!H24:J24))/D21) -> 0.048806088 | E42: =IF(E21=0,0,(SUM('Monthly P&L'!K21:M21)+SUM('Monthly P&L'!K24:M24))/E21) -> 0.048470318 | F42: =IF(F21=0,0,(SUM('Monthly P&L'!N21:P21)+SUM('Monthly P&L'!N24:P24))/F21) -> 0.040629096 | G42: =IF(G21=0,0,(SUM('Monthly P&L'!Q21:S21)+SUM('Monthly P&L'!Q24:S24))/G21) -> 0.04042248 | H42: =IF(H21=0,0,(SUM('Monthly P&L'!T21:V21)+SUM('Monthly P&L'!T24:V24))/H21) -> 0.040230134 | I42: =IF(I21=0,0,(SUM('Monthly P&L'!W21:Y21)+SUM('Monthly P&L'!W24:Y24))/I21) -> 0.040010325 | J42: =IF(J21=0,0,(SUM('Monthly P&L'!B21:Y21)+SUM('Monthly P&L'!B24:Y24))/J21) -> 0.051009564
A44: KEY METRICS (formula-driven)
A45: Peak Cash Need (max of all quarters) | B45: =J27 -> 0
A46: 24-Month Cumulative P&L | B46: =J24 -> -93211
A47: 24-Month Total Revenue | B47: =J11 -> 52644
...

Sheet Sensitivity Analysis
A1: SENSITIVITY ANALYSIS
A2: SECTION 1: Live model output (formula-driven from Assumptions + Monthly P&L)
A3: SECTION 2: Pre-computed scenario tables (what happens when you change ONE variable)
A5: LIVE MODEL OUTPUT (auto-updates from Assumptions)
A6: Metric | B6: Current Value | C6: Formula Source
A7: Current Nav Price | B7: =Assumptions!$B$5 -> 9.99 | C7: Assumptions!B5
A8: Current Pro Price | B8: =Assumptions!$B$6 -> 19.99 | C8: Assumptions!B6
A9: Blended ARPU | B9: =Assumptions!$B$5*(1-Assumptions!$B$7)+Assumptions!$B$6*Assumptions!$B$7 -> 12.49 | C9: Nav*(1-ProPct)+Pro*ProPct
A10: Current Churn Rate | B10: =Assumptions!$B$18 -> 0.07 | C10: Assumptions!B18
A11: Current API Cost/User | B11: =Assumptions!$B$39 -> 1.25 | C11: Assumptions!B39
A13: Mo 24 Paid Subscribers | B13: ='Monthly P&L'!Y5 -> 145 | C13: P&L row 5, col Y (Mo24)
A14: Mo 24 RC Users | B14: ='Monthly P&L'!Y6 -> 34 | C14: P&L row 6, col Y
A15: Mo 24 Total Users | B15: ='Monthly P&L'!Y5+'Monthly P&L'!Y6 -> 179 | C15: Subs + RC
A16: Mo 24 Monthly Revenue | B16: ='Monthly P&L'!Y15 -> 4811 | C16: P&L Total Revenue Mo24
A17: Mo 24 Monthly Costs | B17: ='Monthly P&L'!Y26 -> 8266 | C17: P&L Total Costs Mo24
A18: Mo 24 Net Income | B18: ='Monthly P&L'!Y29 -> -3455 | C18: P&L Net Income Mo24
A19: Mo 24 Ann. Run Rate | B19: ='Monthly P&L'!Y15*12 -> 57732 | C19: Mo24 Revenue × 12
A21: 24-Mo Total Revenue | B21: ='Monthly P&L'!Z15 -> 52644 | C21: P&L Total col (Z), Revenue
A22: 24-Mo Total Costs | B22: ='Monthly P&L'!Z26 -> 145855 | C22: P&L Total col (Z), Costs
A23: 24-Mo Net Income | B23: ='Monthly P&L'!Z29 -> -93211 | C23: P&L Total col (Z), Net
A24: 24-Mo Cumulative P&L | B24: ='Monthly P&L'!Y31 -> -93211 | C24: P&L Cumulative row, Mo24
A26: Total Founder Salary | B26: ='Monthly P&L'!Z25 -> 78000 | C26: P&L Total col, Salary row
A27: Salary % of Costs | B27: =IF('Monthly P&L'!Z26=0,0,'Monthly P&L'!Z25/'Monthly P&L'!Z26) -> 0.53477769 | C27: Salary / Total Costs
A28: Avg Gross Margin | B28: =AVERAGE('Monthly P&L'!B30:Y30) -> 0.74846547 | C28: Avg of GM% row
A30: Founder Salary Mo 1-6 | B30: =Assumptions!$B$53 -> 2000 | C30: Assumptions!B53
A31: Founder Salary Mo 7-12 | B31: =Assumptions!$B$54 -> 3000 | C31: Assumptions!B54
A32: Founder Salary Mo 13-24 | B32: =Assumptions!$B$55 -> 4000 | C32: Assumptions!B55
A33: Monthly Salary (current Mo 1) | B33: ='Monthly P&L'!B25 -> 2000 | C33: P&L Salary row, Mo1
A35: BREAKEVEN ANALYSIS (formula-driven)
A36: First Month Net > 0 | B36: =IFERROR(MATCH(TRUE(),INDEX('Monthly P&L'!B29:Y29>0,0),0),"Never") -> Never | C36: MATCH finds first month where Net Income > 0
A37: Peak Cash Need (personal investment) | B37: =-MIN('Monthly P&L'!B31:Y31) -> 93211 | C37: Negative of minimum cumulative P&L
A38: Month of Peak Cash Need | B38: =MATCH(MIN('Monthly P&L'!B31:Y31),'Monthly P&L'!B31:Y31,0) -> 24 | C38: Month number where cumulative is lowest
A39: RC Revenue % of Mo24 Total | B39: =IF('Monthly P&L'!Y15=0,0,'Monthly P&L'!Y12/'Monthly P&L'!Y15) -> 0.088339223 | C39: Concentration risk: if >70%, model depends on RC
A42: PRE-COMPUTED SCENARIO TABLES | C42: (Reference data — change Assumptions tab for live updates above)
A43: Mo 1-6 Growth Rate
A44: Input Value | B44: 0.1 | C44: 0.15 | D44: 0.2 | E44: 0.25 | F44: 0.3 | G44: 0.4 | H44: 0.5
A45: 24-Mo Net Income | B45: -94617 | C45: -94196 | D45: -93855 | E45: -93222 | F45: -92755 | G45: -91393 | H45: -89960
A46: 24-Mo Total Revenue | B46: 51033 | C46: 51521 | D46: 51907 | E46: 52631 | F46: 53170 | G46: 54728 | H46: 56366
A47: Month 24 Subscribers | B47: 143 | C47: 144 | D47: 144 | E47: 145 | F47: 146 | G47: 150 | H47: 153
A48: Δ vs Default | B48: -1395 | C48: -974 | D48: -633 | E48: 0 | F48: 467 | G48: 1829 | H48: 3262
...
